The following values were not passed to `accelerate launch` and had defaults used instead:
	`--num_processes` was set to a value of `1`
	`--num_machines` was set to a value of `1`
	`--mixed_precision` was set to a value of `'no'`
	`--dynamo_backend` was set to a value of `'no'`
To avoid this warning pass in values for each of the problematic parameters or run `accelerate config`.
/opt/conda/bin/python3.10: can't open file '/home/khj6051/tts_sfx/datas/train_clone.py': [Errno 2] No such file or directory
Traceback (most recent call last):
  File "/opt/conda/bin/accelerate", line 8, in <module>
    sys.exit(main())
  File "/opt/conda/lib/python3.10/site-packages/accelerate/commands/accelerate_cli.py", line 48, in main
    args.func(args)
  File "/opt/conda/lib/python3.10/site-packages/accelerate/commands/launch.py", line 1168, in launch_command
    simple_launcher(args)
  File "/opt/conda/lib/python3.10/site-packages/accelerate/commands/launch.py", line 763, in simple_launcher
    raise subprocess.CalledProcessError(returncode=process.returncode, cmd=cmd)
subprocess.CalledProcessError: Command '['/opt/conda/bin/python3.10', 'train_clone.py']' returned non-zero exit status 2.
The following values were not passed to `accelerate launch` and had defaults used instead:
	`--num_processes` was set to a value of `1`
	`--num_machines` was set to a value of `1`
	`--mixed_precision` was set to a value of `'no'`
	`--dynamo_backend` was set to a value of `'no'`
To avoid this warning pass in values for each of the problematic parameters or run `accelerate config`.
/opt/conda/bin/python3.10: can't open file '/home/khj6051/tts_sfx/datas/train_clone.py': [Errno 2] No such file or directory
Traceback (most recent call last):
  File "/opt/conda/bin/accelerate", line 8, in <module>
    sys.exit(main())
  File "/opt/conda/lib/python3.10/site-packages/accelerate/commands/accelerate_cli.py", line 48, in main
    args.func(args)
  File "/opt/conda/lib/python3.10/site-packages/accelerate/commands/launch.py", line 1168, in launch_command
    simple_launcher(args)
  File "/opt/conda/lib/python3.10/site-packages/accelerate/commands/launch.py", line 763, in simple_launcher
    raise subprocess.CalledProcessError(returncode=process.returncode, cmd=cmd)
subprocess.CalledProcessError: Command '['/opt/conda/bin/python3.10', 'train_clone.py']' returned non-zero exit status 2.
